2025-05-04 03:14:59,707 INFO    MainThread:78817 [wandb_setup.py:_flush():68] Current SDK version is 0.19.10
2025-05-04 03:14:59,707 INFO    MainThread:78817 [wandb_setup.py:_flush():68] Configure stats pid to 78817
2025-05-04 03:14:59,707 INFO    MainThread:78817 [wandb_setup.py:_flush():68] Loading settings from /root/.config/wandb/settings
2025-05-04 03:14:59,707 INFO    MainThread:78817 [wandb_setup.py:_flush():68] Loading settings from /home/code/LSTMBard/wandb/settings
2025-05-04 03:14:59,708 INFO    MainThread:78817 [wandb_setup.py:_flush():68] Loading settings from environment variables
2025-05-04 03:14:59,708 INFO    MainThread:78817 [wandb_init.py:setup_run_log_directory():724] Logging user logs to /home/code/LSTMBard/wandb/run-20250504_031459-x1xkzkcb/logs/debug.log
2025-05-04 03:14:59,708 INFO    MainThread:78817 [wandb_init.py:setup_run_log_directory():725] Logging internal logs to /home/code/LSTMBard/wandb/run-20250504_031459-x1xkzkcb/logs/debug-internal.log
2025-05-04 03:14:59,708 INFO    MainThread:78817 [wandb_init.py:init():852] calling init triggers
2025-05-04 03:14:59,708 INFO    MainThread:78817 [wandb_init.py:init():857] wandb.init called with sweep_config: {}
config: {'learning_rate': 0.001, 'epochs': 50, 'model_type': 'PoemLSTM', 'embedding_dim': 256, 'hidden_dim': 512, 'num_layers': 3, 'vocab_size': 8293, '_wandb': {}}
2025-05-04 03:14:59,708 INFO    MainThread:78817 [wandb_init.py:init():893] starting backend
2025-05-04 03:14:59,709 INFO    MainThread:78817 [wandb_init.py:init():897] sending inform_init request
2025-05-04 03:14:59,767 INFO    MainThread:78817 [backend.py:_multiprocessing_setup():101] multiprocessing start_methods=fork,spawn,forkserver, using: spawn
2025-05-04 03:14:59,767 INFO    MainThread:78817 [wandb_init.py:init():907] backend started and connected
2025-05-04 03:14:59,770 INFO    MainThread:78817 [wandb_init.py:init():1002] updated telemetry
2025-05-04 03:14:59,850 INFO    MainThread:78817 [wandb_init.py:init():1026] communicating run to backend with 90.0 second timeout
2025-05-04 03:15:31,768 INFO    Thread-2  :78817 [retry.py:__call__():175] [no run ID] Retry attempt failed:
Traceback (most recent call last):
  File "/home/Minconda3/envs/clip/lib/python3.8/site-packages/urllib3/connectionpool.py", line 536, in _make_request
    response = conn.getresponse()
  File "/home/Minconda3/envs/clip/lib/python3.8/site-packages/urllib3/connection.py", line 507, in getresponse
    httplib_response = super().getresponse()
  File "/home/Minconda3/envs/clip/lib/python3.8/http/client.py", line 1348, in getresponse
    response.begin()
  File "/home/Minconda3/envs/clip/lib/python3.8/http/client.py", line 316, in begin
    version, status, reason = self._read_status()
  File "/home/Minconda3/envs/clip/lib/python3.8/http/client.py", line 277, in _read_status
    line = str(self.fp.readline(_MAXLINE + 1), "iso-8859-1")
  File "/home/Minconda3/envs/clip/lib/python3.8/socket.py", line 681, in readinto
    return self._sock.recv_into(b)
  File "/home/Minconda3/envs/clip/lib/python3.8/ssl.py", line 1274, in recv_into
    return self.read(nbytes, buffer)
  File "/home/Minconda3/envs/clip/lib/python3.8/ssl.py", line 1132, in read
    return self._sslobj.read(len, buffer)
socket.timeout: The read operation timed out

The above exception was the direct cause of the following exception:

Traceback (most recent call last):
  File "/home/Minconda3/envs/clip/lib/python3.8/site-packages/requests/adapters.py", line 667, in send
    resp = conn.urlopen(
  File "/home/Minconda3/envs/clip/lib/python3.8/site-packages/urllib3/connectionpool.py", line 843, in urlopen
    retries = retries.increment(
  File "/home/Minconda3/envs/clip/lib/python3.8/site-packages/urllib3/util/retry.py", line 474, in increment
    raise reraise(type(error), error, _stacktrace)
  File "/home/Minconda3/envs/clip/lib/python3.8/site-packages/urllib3/util/util.py", line 39, in reraise
    raise value
  File "/home/Minconda3/envs/clip/lib/python3.8/site-packages/urllib3/connectionpool.py", line 789, in urlopen
    response = self._make_request(
  File "/home/Minconda3/envs/clip/lib/python3.8/site-packages/urllib3/connectionpool.py", line 538, in _make_request
    self._raise_timeout(err=e, url=url, timeout_value=read_timeout)
  File "/home/Minconda3/envs/clip/lib/python3.8/site-packages/urllib3/connectionpool.py", line 369, in _raise_timeout
    raise ReadTimeoutError(
urllib3.exceptions.ReadTimeoutError: HTTPSConnectionPool(host='api.wandb.ai', port=443): Read timed out. (read timeout=20)

During handling of the above exception, another exception occurred:

Traceback (most recent call last):
  File "/home/Minconda3/envs/clip/lib/python3.8/site-packages/wandb/sdk/lib/retry.py", line 134, in __call__
    result = self._call_fn(*args, **kwargs)
  File "/home/Minconda3/envs/clip/lib/python3.8/site-packages/wandb/sdk/internal/internal_api.py", line 402, in execute
    return self.client.execute(*args, **kwargs)  # type: ignore
  File "/home/Minconda3/envs/clip/lib/python3.8/site-packages/wandb/vendor/gql-0.2.0/wandb_gql/client.py", line 52, in execute
    result = self._get_result(document, *args, **kwargs)
  File "/home/Minconda3/envs/clip/lib/python3.8/site-packages/wandb/vendor/gql-0.2.0/wandb_gql/client.py", line 60, in _get_result
    return self.transport.execute(document, *args, **kwargs)
  File "/home/Minconda3/envs/clip/lib/python3.8/site-packages/wandb/sdk/lib/gql_request.py", line 58, in execute
    request = self.session.post(self.url, **post_args)
  File "/home/Minconda3/envs/clip/lib/python3.8/site-packages/requests/sessions.py", line 637, in post
    return self.request("POST", url, data=data, json=json, **kwargs)
  File "/home/Minconda3/envs/clip/lib/python3.8/site-packages/requests/sessions.py", line 589, in request
    resp = self.send(prep, **send_kwargs)
  File "/home/Minconda3/envs/clip/lib/python3.8/site-packages/requests/sessions.py", line 703, in send
    r = adapter.send(request, **kwargs)
  File "/home/Minconda3/envs/clip/lib/python3.8/site-packages/requests/adapters.py", line 713, in send
    raise ReadTimeout(e, request=request)
requests.exceptions.ReadTimeout: HTTPSConnectionPool(host='api.wandb.ai', port=443): Read timed out. (read timeout=20)
2025-05-04 03:15:42,915 WARNING MainThread:78817 [wandb_init.py:init():1654] [no run ID] interrupted
Traceback (most recent call last):
  File "/home/Minconda3/envs/clip/lib/python3.8/site-packages/wandb/sdk/wandb_init.py", line 1650, in init
    return wi.init(run_settings, run_config, run_printer)
  File "/home/Minconda3/envs/clip/lib/python3.8/site-packages/wandb/sdk/wandb_init.py", line 1052, in init
    result = wait_with_progress(
  File "/home/Minconda3/envs/clip/lib/python3.8/site-packages/wandb/sdk/mailbox/wait_with_progress.py", line 24, in wait_with_progress
    return wait_all_with_progress(
  File "/home/Minconda3/envs/clip/lib/python3.8/site-packages/wandb/sdk/mailbox/wait_with_progress.py", line 87, in wait_all_with_progress
    return asyncio_compat.run(progress_loop_with_timeout)
  File "/home/Minconda3/envs/clip/lib/python3.8/site-packages/wandb/sdk/lib/asyncio_compat.py", line 30, in run
    return future.result()
  File "/home/Minconda3/envs/clip/lib/python3.8/concurrent/futures/_base.py", line 439, in result
    self._condition.wait(timeout)
  File "/home/Minconda3/envs/clip/lib/python3.8/threading.py", line 302, in wait
    waiter.acquire()
KeyboardInterrupt
